{"name": "test_second", "status": "failed", "statusDetails": {"message": "AssertionError: 2 не равно 3\nassert 2 == 3", "trace": "def test_second():\n>       assert 2 == 3, \"2 не равно 3\"\nE       AssertionError: 2 не равно 3\nE       assert 2 == 3\n\ntests\\ui\\test_first.py:49: AssertionError"}, "start": 1725623020976, "stop": 1725623020976, "uuid": "7b7537f7-596f-419b-bf0b-12bbca81e931", "historyId": "7876f628adff9d99e805e093c315ee0a", "testCaseId": "7876f628adff9d99e805e093c315ee0a", "fullName": "tests.ui.test_first#test_second", "labels": [{"name": "parentSuite", "value": "tests.ui"}, {"name": "suite", "value": "test_first"}, {"name": "host", "value": "A2071"}, {"name": "thread", "value": "184108-MainThread"}, {"name": "framework", "value": "pytest"}, {"name": "language", "value": "cpython3"}, {"name": "package", "value": "tests.ui.test_first"}]}